<?xml version="1.0"?>
<robot name="pole_box_robot">

  <link name="world"/>

  <link name="base_link">
    <visual>
      <geometry>
        <cylinder radius="0.5" length="0.2"/>
      </geometry>
      <material name="gray">
        <color rgba="0.5 0.5 0.5 1.0"/>
      </material>
    </visual>
    <collision>
      <geometry>
        <cylinder radius="0.5" length="0.2"/>
      </geometry>
    </collision>
    <inertial>
      <mass value="50.0"/>
      <inertia ixx="3.385" ixy="0" ixz="0" iyy="3.385" iyz="0" izz="6.25"/>
    </inertial>
  </link>

  <link name="pole_link">
    <visual>
      <geometry>
        <cylinder radius="0.05" length="3.0"/>
      </geometry>
      <material name="blue">
        <color rgba="0.0 0.0 1.0 1.0"/>
      </material>
    </visual>
    <collision>
      <geometry>
        <cylinder radius="0.05" length="3.0"/>
      </geometry>
    </collision>
    <inertial>
      <mass value="0.5"/>
      <origin xyz="0 0 0" rpy="0 0 0"/>
      <inertia ixx="0.375" ixy="0" ixz="0" iyy="0.375" iyz="0" izz="0.000625"/>
    </inertial>
  </link>

  <link name="box_link">
    <visual>
      <geometry>
        <box size="0.4 0.8 0.2"/>
      </geometry>
      <material name="red">
        <color rgba="1.0 0.0 0.0 1.0"/>
      </material>
    </visual>
    <collision>
      <geometry>
        <box size="0.4 0.8 0.2"/>
      </geometry>
    </collision>
    <inertial>
      <mass value="0.2"/>
      <origin xyz="0 0 0" rpy="0 0 0"/>
      <inertia ixx="0.01067" ixy="0" ixz="0" iyy="0.00533" iyz="0" izz="0.01067"/>
    </inertial>
  </link>

  <joint name="world_to_base" type="fixed">
    <parent link="world"/>
    <child link="base_link"/>
    <origin xyz="0 0 0" rpy="0 0 0"/>
  </joint>

  <joint name="base_to_pole" type="continuous">
    <parent link="base_link"/>
    <child link="pole_link"/>
    <origin xyz="0 0 1.6" rpy="0 0 0"/>
    <axis xyz="0 0 1"/>
    <limit lower="-3.14159" upper="3.14159" effort="100" velocity="1.0"/>
    <dynamics damping="1.0" friction="0.1"/>
  </joint>

  <joint name="pole_to_box" type="fixed">
    <parent link="pole_link"/>
    <child link="box_link"/>
    <origin xyz="0 0 1.6" rpy="0 0 0"/>
  </joint>

  <!-- ros2_control for Gazebo Harmonic
  <ros2_control name="GazeboSimSystem" type="system">
    <hardware>
      <plugin>gz_ros2_control/GazeboSimSystem</plugin>
    </hardware>
    <joint name="base_to_pole">
      <command_interface name="position">
        <param name="min">-3.14159</param>
        <param name="max">3.14159</param>
      </command_interface>
      <state_interface name="position">
        <param name="initial_value">0.0</param>
      </state_interface>
      <state_interface name="velocity"/>
      <state_interface name="effort"/>
    </joint>
  </ros2_control>

  <! Gazebo Harmonic plugin >
  <gazebo>
    <plugin filename="libgz_ros2_control-system.so" name="gz_ros2_control::GazeboSimROS2ControlPlugin">
      <robot_param>robot_description</robot_param>
      <robot_param_node>robot_state_publisher</robot_param_node>
    </plugin>
  </gazebo> -->
  
  <ros2_control name="GazeboSystem" type="system">
  <hardware>
    <plugin>gazebo_ros2_control/GazeboSystem</plugin>
  </hardware>
  <joint name="base_to_pole" >
     <command_interface name="position" />
     <command_interface name="velocity" />
     <state_interface name="position"/>
     <state_interface name="velocity"/>
  </joint>
  </ros2_control>

  <gazebo>
  <plugin filename="libgazebo_ros2_control.so" name="gazebo_ros2_control">
    <parameters>$(find husky_footplcmt)/config/pole_camera_test.yaml</parameters>
  </plugin>
  </gazebo>
</robot>